Workbook

Sheet Resumen
A1: CIPHER-LAC · Informe de avances 2026
A2: Collaborative Initiative for Public Health and Epidemiological Research in Latin America and the Caribbean · Universidad Científica del Sur, Lima, Perú
B4: Dirigido a: | C4: Dirección de Investigación – Universidad Científica del Sur
B5: Fecha de corte: | C5: 46287
B6: Presentado por: | C6: Liderazgo del grupo CIPHER-LAC
B7: Fuente: | C7: Archivo «PROYECTOS DE INVESTIGACIÓN Y TESIS» del grupo (6 hojas)
B9: Indicadores clave | P9: Datos para gráficos
B10: Indicador | C10: Valor | D10: Hoja de detalle | P10: Estado | Q10: N.º
B11: PROYECTOS DE INVESTIGACIÓN | P11: Publicado | Q11: ='Producción científica'!C17 -> 4
B12: Proyectos y propuestas registrados en 2026 | C12: =COUNTA('Proyectos 2026'!B5:B14) -> 10 | D12: Proyectos 2026 | P12: Aceptado | Q12: ='Producción científica'!C18 -> 1
B13: En ejecución | C13: =COUNTIF('Proyectos 2026'!Q5:Q14,"En ejecución") -> 3 | D13: Proyectos 2026 | P13: Sometido | Q13: ='Producción científica'!C19 -> 3
B14: Finalizados (con manuscrito publicado, aceptado o sometido) | C14: =COUNTIF('Proyectos 2026'!Q5:Q14,"Finalizado*") -> 4 | D14: Proyectos 2026
B15: En desarrollo, formulación o por iniciar | C15: =C12-C13-C14 -> 3 | D15: Proyectos 2026 | P15: Programa | Q15: Tesis
B16: Con protocolo registrado | C16: =COUNTIF('Proyectos 2026'!N5:N14,"Sí") -> 3 | D16: Proyectos 2026 | P16: Maestría Epidemiología Clínica y Bioestadística | Q16: ='Tesis 2026'!C20 -> 5
B17: Con financiamiento externo o en concurso | C17: =COUNTIF('Proyectos 2026'!I5:I14,"<>Sin financiamiento") -> 3 | D17: Proyectos 2026 | P17: Maestría Salud Pública | Q17: ='Tesis 2026'!C21 -> 3
B18: Con colaboración de otros grupos o internacional | C18: =COUNTIF('Proyectos 2026'!E5:E14,"*;*")+COUNTIF('Proyectos 2026'!C5:C14,"*España*") -> 5 | D18: Proyectos 2026 | P18: Medicina Veterinaria y Zootecnia | Q18: ='Tesis 2026'!C22 -> 2
B19: PRODUCCIÓN CIENTÍFICA | P19: Medicina Humana | Q19: ='Tesis 2026'!C23 -> 1
B20: Artículos publicados en 2026 | C20: =COUNTIF('Producción científica'!G5:G12,"Publicado") -> 4 | D20: Producción científica
B21: Manuscritos aceptados | C21: =COUNTIF('Producción científica'!G5:G12,"Aceptado") -> 1 | D21: Producción científica | P21: Línea UCSUR | Q21: Registros
B22: Manuscritos sometidos (en revisión) | C22: =COUNTIF('Producción científica'!G5:G12,"Sometido") -> 3 | D22: Producción científica | P22: ='Líneas UCSUR'!C29 -> Neurociencias y salud mental | Q22: ='Líneas UCSUR'!H29 -> 9
B23: FORMACIÓN DE INVESTIGADORES (TESIS) | P23: ='Líneas UCSUR'!C28 -> Microbiología, infecciosas y one health | Q23: ='Líneas UCSUR'!H28 -> 7
B24: Tesis en curso / asesoradas | C24: =COUNTA('Tesis 2026'!B5:B15) -> 11 | D24: Tesis 2026 | P24: ='Líneas UCSUR'!C27 -> Inmunidad, cáncer y enfermedades crónicas | Q24: ='Líneas UCSUR'!H27 -> 5
B25: De posgrado (maestría) | C25: =COUNTIF('Tesis 2026'!F5:F15,"Posgrado") -> 8 | D25: Tesis 2026 | P25: ='Líneas UCSUR'!C33 -> Salud pública, salud ocupacional y gestión en salud | Q25: ='Líneas UCSUR'!H33 -> 4
B26: De pregrado | C26: =COUNTIF('Tesis 2026'!F5:F15,"Pregrado") -> 3 | D26: Tesis 2026 | P26: ='Líneas UCSUR'!C30 -> Nutrición, bienestar y actividad física | Q26: ='Líneas UCSUR'!H30 -> 2
B27: Registradas | C27: =COUNTIF('Tesis 2026'!H5:H15,"Registrada") -> 9 | D27: Tesis 2026 | P27: ='Líneas UCSUR'!C32 -> Salud basada en evidencias | Q27: ='Líneas UCSUR'!H32 -> 1
B28: Pendientes de registro | C28: =COUNTIF('Tesis 2026'!H5:H15,"Pendiente de registro") -> 2 | D28: Tesis 2026 | P28: ='Líneas UCSUR'!C26 -> Estomatología y salud bucodental | Q28: ='Líneas UCSUR'!H26 -> 1
B29: Con 2 años o más desde su registro | C29: =COUNTIF('Tesis 2026'!I5:I15,">=2") -> 3 | D29: Tesis 2026 | P29: ='Líneas UCSUR'!C40 -> Innovación educativa y simulación en salud | Q29: ='Líneas UCSUR'!H40 -> 1
B30: FONDOS CONCURSABLES Y DIFUSIÓN
B31: Postulaciones a fondos concursables | C31: =COUNTA(Postulaciones!C5:C5) -> 1 | D31: Postulaciones
B32: Proyectos en concurso interno (Semilla Cabieses) | C32: =COUNTIF('Proyectos 2026'!H5:H14,"*Cabieses*") -> 2 | D32: Postulaciones
B33: Webinars de difusión CTI registrados | C33: ='Difusión CTI'!C16 -> 0 | D33: Difusión CTI
B34: EQUIPO Y ALINEAMIENTO INSTITUCIONAL
B35: Integrantes con participación registrada | C35: =Equipo!C34 -> 28 | D35: Equipo
B36: De ellos, tesistas | C36: =Equipo!C35 -> 11 | D36: Equipo
B37: Líneas de investigación UCSUR con actividad del grupo | C37: =COUNTIF('Líneas UCSUR'!I5:I41,"Sí") -> 8 | D37: Líneas UCSUR
B38: Áreas estratégicas UCSUR con actividad del grupo | C38: =COUNTIF('Líneas UCSUR'!E47:E51,">0") -> 2 | D38: Líneas UCSUR
B39: Acciones de seguimiento identificadas (prioridad alta) | C39: =COUNTIF('Pendientes y acciones'!G5:G40,"Alta") -> 5 | D39: Pendientes y acciones
B41: Logros destacados del periodo
B42: • Cuatro artículos publicados en 2026 con filiación CIPHER-LAC en revistas internacionales: Scientific Reports, Autism in Adulthood, Therapeutic Innovation & Regulatory Science y Medical Sciences.
B43: • Cartera de manuscritos en proceso: uno aceptado (Psychodynamic Psychiatry) y tres sometidos (Journal of Technology in Behavioral Science; Frontiers / PLOS ONE).
...

Sheet Líneas UCSUR
A1: Alineamiento con las líneas de investigación institucionales de la UCSUR
A2: Fuente: hoja «LINEAS DE INVESTIGACION» (37 líneas en 5 áreas estratégicas). Los conteos se calculan automáticamente a partir de la línea asignada en cada hoja del informe.
A4: N.º | B4: Área estratégica | C4: Línea de investigación | D4: Proyectos 2026 | E4: Artículos y manuscritos | F4: Tesis | G4: Postulaciones | H4: Total de registros | I4: ¿Línea activa en CIPHER-LAC?
A5: 1 | B5: Ambiente y biodiversidad | C5: Cambio climático y agua | D5: =COUNTIF('Proyectos 2026'!$F$5:$F$14,C5) -> 0 | E5: =COUNTIF('Producción científica'!$I$5:$I$12,C5) -> 0 | F5: =COUNTIF('Tesis 2026'!$L$5:$L$15,C5) -> 0 | G5: =COUNTIF(Postulaciones!$I$5:$I$5,C5) -> 0 | H5: =SUM(D5:G5) -> 0 | I5: =IF(H5>0,"Sí","—") -> —
A6: 2 | B6: Ambiente y biodiversidad | C6: Conservación y gestión de ecosistemas antárticos | D6: =COUNTIF('Proyectos 2026'!$F$5:$F$14,C6) -> 0 | E6: =COUNTIF('Producción científica'!$I$5:$I$12,C6) -> 0 | F6: =COUNTIF('Tesis 2026'!$L$5:$L$15,C6) -> 0 | G6: =COUNTIF(Postulaciones!$I$5:$I$5,C6) -> 0 | H6: =SUM(D6:G6) -> 0 | I6: =IF(H6>0,"Sí","—") -> —
A7: 3 | B7: Ambiente y biodiversidad | C7: Ecosistemas marinos, costeros, dulceacuícolas | D7: =COUNTIF('Proyectos 2026'!$F$5:$F$14,C7) -> 0 | E7: =COUNTIF('Producción científica'!$I$5:$I$12,C7) -> 0 | F7: =COUNTIF('Tesis 2026'!$L$5:$L$15,C7) -> 0 | G7: =COUNTIF(Postulaciones!$I$5:$I$5,C7) -> 0 | H7: =SUM(D7:G7) -> 0 | I7: =IF(H7>0,"Sí","—") -> —
A8: 4 | B8: Ambiente y biodiversidad | C8: Gestión, sostenibilidad y calidad ambiental | D8: =COUNTIF('Proyectos 2026'!$F$5:$F$14,C8) -> 0 | E8: =COUNTIF('Producción científica'!$I$5:$I$12,C8) -> 0 | F8: =COUNTIF('Tesis 2026'!$L$5:$L$15,C8) -> 0 | G8: =COUNTIF(Postulaciones!$I$5:$I$5,C8) -> 0 | H8: =SUM(D8:G8) -> 0 | I8: =IF(H8>0,"Sí","—") -> —
A9: 5 | B9: Ambiente y biodiversidad | C9: Recursos naturales y energías renovables | D9: =COUNTIF('Proyectos 2026'!$F$5:$F$14,C9) -> 0 | E9: =COUNTIF('Producción científica'!$I$5:$I$12,C9) -> 0 | F9: =COUNTIF('Tesis 2026'!$L$5:$L$15,C9) -> 0 | G9: =COUNTIF(Postulaciones!$I$5:$I$5,C9) -> 0 | H9: =SUM(D9:G9) -> 0 | I9: =IF(H9>0,"Sí","—") -> —
A10: 6 | B10: Ambiente y biodiversidad | C10: Regulación ambiental y conservación de la biodiversidad | D10: =COUNTIF('Proyectos 2026'!$F$5:$F$14,C10) -> 0 | E10: =COUNTIF('Producción científica'!$I$5:$I$12,C10) -> 0 | F10: =COUNTIF('Tesis 2026'!$L$5:$L$15,C10) -> 0 | G10: =COUNTIF(Postulaciones!$I$5:$I$5,C10) -> 0 | H10: =SUM(D10:G10) -> 0 | I10: =IF(H10>0,"Sí","—") -> —
A11: 7 | B11: Desarrollo sostenible | C11: Cadenas productivas sostenibles y economía azul | D11: =COUNTIF('Proyectos 2026'!$F$5:$F$14,C11) -> 0 | E11: =COUNTIF('Producción científica'!$I$5:$I$12,C11) -> 0 | F11: =COUNTIF('Tesis 2026'!$L$5:$L$15,C11) -> 0 | G11: =COUNTIF(Postulaciones!$I$5:$I$5,C11) -> 0 | H11: =SUM(D11:G11) -> 0 | I11: =IF(H11>0,"Sí","—") -> —
A12: 8 | B12: Desarrollo sostenible | C12: Conectividad, transporte y seguridad | D12: =COUNTIF('Proyectos 2026'!$F$5:$F$14,C12) -> 0 | E12: =COUNTIF('Producción científica'!$I$5:$I$12,C12) -> 0 | F12: =COUNTIF('Tesis 2026'!$L$5:$L$15,C12) -> 0 | G12: =COUNTIF(Postulaciones!$I$5:$I$5,C12) -> 0 | H12: =SUM(D12:G12) -> 0 | I12: =IF(H12>0,"Sí","—") -> —
A13: 9 | B13: Desarrollo sostenible | C13: Innovación agraria, desarrollo rural y cultivos estratégicos | D13: =COUNTIF('Proyectos 2026'!$F$5:$F$14,C13) -> 0 | E13: =COUNTIF('Producción científica'!$I$5:$I$12,C13) -> 0 | F13: =COUNTIF('Tesis 2026'!$L$5:$L$15,C13) -> 0 | G13: =COUNTIF(Postulaciones!$I$5:$I$5,C13) -> 0 | H13: =SUM(D13:G13) -> 0 | I13: =IF(H13>0,"Sí","—") -> —
A14: 10 | B14: Desarrollo sostenible | C14: Innovación en la construcción y urbanismo sostenible | D14: =COUNTIF('Proyectos 2026'!$F$5:$F$14,C14) -> 0 | E14: =COUNTIF('Producción científica'!$I$5:$I$12,C14) -> 0 | F14: =COUNTIF('Tesis 2026'!$L$5:$L$15,C14) -> 0 | G14: =COUNTIF(Postulaciones!$I$5:$I$5,C14) -> 0 | H14: =SUM(D14:G14) -> 0 | I14: =IF(H14>0,"Sí","—") -> —
A15: 11 | B15: Desarrollo sostenible | C15: Producción animal sostenible y seguridad alimentaria | D15: =COUNTIF('Proyectos 2026'!$F$5:$F$14,C15) -> 0 | E15: =COUNTIF('Producción científica'!$I$5:$I$12,C15) -> 0 | F15: =COUNTIF('Tesis 2026'!$L$5:$L$15,C15) -> 0 | G15: =COUNTIF(Postulaciones!$I$5:$I$5,C15) -> 0 | H15: =SUM(D15:G15) -> 0 | I15: =IF(H15>0,"Sí","—") -> —
A16: 12 | B16: Empresa y tecnología | C16: Comercio exterior y negocios internacionales | D16: =COUNTIF('Proyectos 2026'!$F$5:$F$14,C16) -> 0 | E16: =COUNTIF('Producción científica'!$I$5:$I$12,C16) -> 0 | F16: =COUNTIF('Tesis 2026'!$L$5:$L$15,C16) -> 0 | G16: =COUNTIF(Postulaciones!$I$5:$I$5,C16) -> 0 | H16: =SUM(D16:G16) -> 0 | I16: =IF(H16>0,"Sí","—") -> —
... A41: 37 | B41: Sociedad y ciudadanía | C41: Turismo, artes e industrias culturales | D41: =COUNTIF('Proyectos 2026'!$F$5:$F$14,C41) -> 0 | E41: =COUNTIF('Producción científica'!$I$5:$I$12,C41) -> 0 | F41: =COUNTIF('Tesis 2026'!$L$5:$L$15,C41) -> 0 | G41: =COUNTIF(Postulaciones!$I$5:$I$5,C41) -> 0 | H41: =SUM(D41:G41) -> 0 | I41: =IF(H41>0,"Sí","—") -> —
C42: Total | D42: =SUM(D5:D41) -> 10 | E42: =SUM(E5:E41) -> 8 | F42: =SUM(F5:F41) -> 11 | G42: =SUM(G5:G41) -> 1 | H42: =SUM(H5:H41) -> 30 | I42: =COUNTIF(I5:I41,"Sí")&" de "&COUNTA(C5:C41)&" líneas" -> 8 de 37 líneas
B45: Resumen por área estratégica
B46: Área estratégica | C46: Líneas del área | D46: Líneas activas | E46: Total de registros
B47: Ambiente y biodiversidad | C47: =COUNTIF($B$5:$B$41,B47) -> 6 | D47: =COUNTIFS($B$5:$B$41,B47,$I$5:$I$41,"Sí") -> 0 | E47: =SUMIF($B$5:$B$41,B47,$H$5:$H$41) -> 0
B48: Desarrollo sostenible | C48: =COUNTIF($B$5:$B$41,B48) -> 5 | D48: =COUNTIFS($B$5:$B$41,B48,$I$5:$I$41,"Sí") -> 0 | E48: =SUMIF($B$5:$B$41,B48,$H$5:$H$41) -> 0
B49: Empresa y tecnología | C49: =COUNTIF($B$5:$B$41,B49) -> 8 | D49: =COUNTIFS($B$5:$B$41,B49,$I$5:$I$41,"Sí") -> 0 | E49: =SUMIF($B$5:$B$41,B49,$H$5:$H$41) -> 0
B50: Salud y bienestar | C50: =COUNTIF($B$5:$B$41,B50) -> 11 | D50: =COUNTIFS($B$5:$B$41,B50,$I$5:$I$41,"Sí") -> 7 | E50: =SUMIF($B$5:$B$41,B50,$H$5:$H$41) -> 29
B51: Sociedad y ciudadanía | C51: =COUNTIF($B$5:$B$41,B51) -> 7 | D51: =COUNTIFS($B$5:$B$41,B51,$I$5:$I$41,"Sí") -> 1 | E51: =SUMIF($B$5:$B$41,B51,$H$5:$H$41) -> 1

Sheet Proyectos 2026
A1: Proyectos y propuestas de investigación 2026
A4: N.º | B4: Proyecto / propuesta | C4: Investigador(a) líder | D4: Colaborador(a) externo(a) | E4: Equipo / grupos participantes | F4: Línea de investigación UCSUR | G4: Área estratégica UCSUR | H4: Entidad financiadora | I4: Tipo de financiamiento | J4: Costo monetario estimado* | K4: Costo no monetario estimado | L4: Institución donde se realiza | M4: N.º de registro de protocolo | N4: ¿Protocolo registrado? | O4: Inicio | P4: Fin | Q4: Estado de ejecución | R4: Difusión: artículo (revista y estado) | S4: Estado del manuscrito | T4: Webinar | U4: Incidencia en políticas
A5: 1 | B5: Admisión a UCI y desenlaces de encefalitis autoinmune en América Latina: REAL LABIC Prospectivo | C5: Miguel Ángel Vences | D5: — | E5: REAL LABIC Group; CIPHER-LAC | F5: Neurociencias y salud mental | G5: =IFERROR(INDEX('Líneas UCSUR'!$B$5:$B$41,MATCH(F5,'Líneas UCSUR'!$C$5:$C$41,0)),"") -> Salud y bienestar | H5: Ninguna | I5: Sin financiamiento | J5: Por registrar | K5: Por registrar | L5: UCSUR | M5: Por registrar | N5: =IF(M5="Por registrar","No","Sí") -> No | O5: 46082 | P5: 46357 | Q5: En ejecución | R5: — | S5: — | T5: Por registrar | U5: Por registrar
A6: 2 | B6: Dinámica de la adquisición intrahospitalaria de Enterobacterales de prioridad crítica para la OMS en perros hospitalizados en clínicas veterinarias de Lima, Perú | C6: Por registrar | D6: Jhonathan Bazalar Gonzales | E6: SANIGEN; CIPHER-LAC | F6: Microbiología, infecciosas y one health | G6: =IFERROR(INDEX('Líneas UCSUR'!$B$5:$B$41,MATCH(F6,'Líneas UCSUR'!$C$5:$C$41,0)),"") -> Salud y bienestar | H6: Ninguna | I6: Sin financiamiento | J6: Por registrar | K6: Por registrar | L6: UCSUR | M6: Por registrar | N6: =IF(M6="Por registrar","No","Sí") -> No | O6: Por registrar | P6: Por registrar | Q6: En formulación | R6: — | S6: — | T6: Por registrar | U6: Por registrar
A7: 3 | B7: Búsqueda activa y fortalecimiento de capacidades frente a influenza zoonótica en poblaciones con exposición ocupacional en Lima, Perú: un estudio piloto con enfoque Una Salud | C7: Natalia Vargas Herrera | D7: — | E7: CIPHER-LAC | F7: Microbiología, infecciosas y one health | G7: =IFERROR(INDEX('Líneas UCSUR'!$B$5:$B$41,MATCH(F7,'Líneas UCSUR'!$C$5:$C$41,0)),"") -> Salud y bienestar | H7: TDR-OMS | I7: Externo internacional | J7: 40000 | K7: Por registrar | L7: UCSUR | M7: Por registrar | N7: =IF(M7="Por registrar","No","Sí") -> No | O7: Por registrar | P7: Por registrar | Q7: Por iniciar | R7: — | S7: — | T7: Por registrar | U7: Por registrar
A8: 4 | B8: Effectiveness of structured psychotherapies for alcohol use disorder in adults with personality disorders: a systematic review | C8: Aurora Döll (España) | D8: Glauco Valdivieso Jiménez | E8: CIPHER-LAC | F8: Neurociencias y salud mental | G8: =IFERROR(INDEX('Líneas UCSUR'!$B$5:$B$41,MATCH(F8,'Líneas UCSUR'!$C$5:$C$41,0)),"") -> Salud y bienestar | H8: Ninguna | I8: Sin financiamiento | J8: Por registrar | K8: Por registrar | L8: UCSUR | M8: Por registrar | N8: =IF(M8="Por registrar","No","Sí") -> No | O8: Por registrar | P8: Por registrar | Q8: En desarrollo | R8: — | S8: — | T8: Por registrar | U8: Por registrar
A9: 5 | B9: Neurobiological effects of psychodynamic therapies in Borderline Personality Disorder: A systematic review | C9: Glauco Valdivieso Jiménez | D9: — | E9: CIPHER-LAC | F9: Neurociencias y salud mental | G9: =IFERROR(INDEX('Líneas UCSUR'!$B$5:$B$41,MATCH(F9,'Líneas UCSUR'!$C$5:$C$41,0)),"") -> Salud y bienestar | H9: Ninguna | I9: Sin financiamiento | J9: Por registrar | K9: Por registrar | L9: UCSUR | M9: Por registrar | N9: =IF(M9="Por registrar","No","Sí") -> No | O9: Por registrar | P9: Por registrar | Q9: Finalizado – manuscrito aceptado | R9: Psychodynamic Psychiatry | S9: Aceptado | T9: Por registrar | U9: Por registrar
A10: 6 | B10: Effects of cognitive behavioral therapy in adults with autism spectrum disorder: A systematic review and meta-analysis of randomized controlled trials | C10: Jesús Pérez Castilla | D10: Glauco Valdivieso Jiménez | E10: CIPHER-LAC | F10: Neurociencias y salud mental | G10: =IFERROR(INDEX('Líneas UCSUR'!$B$5:$B$41,MATCH(F10,'Líneas UCSUR'!$C$5:$C$41,0)),"") -> Salud y bienestar | H10: Ninguna | I10: Sin financiamiento | J10: Por registrar | K10: Por registrar | L10: UCSUR | M10: Por registrar | N10: =IF(M10="Por registrar","No","Sí") -> No | O10: Por registrar | P10: Por registrar | Q10: Finalizado – publicado | R10: Autism in Adulthood | S10: Publicado | T10: Por registrar | U10: Por registrar
A11: 7 | B11: Efectividad de intervenciones virtuales para el Trastorno Límite de Personalidad antes y durante pandemia de COVID-19: una revisión sistemática | C11: Glauco Valdivieso Jiménez | D11: — | E11: CIPHER-LAC | F11: Neurociencias y salud mental | G11: =IFERROR(INDEX('Líneas UCSUR'!$B$5:$B$41,MATCH(F11,'Líneas UCSUR'!$C$5:$C$41,0)),"") -> Salud y bienestar | H11: Ninguna | I11: Sin financiamiento | J11: Por registrar | K11: Por registrar | L11: Por registrar | M11: Por registrar | N11: =IF(M11="Por registrar","No","Sí") -> No | O11: Por registrar | P11: Por registrar | Q11: Finalizado – manuscrito sometido | R11: Journal of Technology in Behavioral Science | S11: Sometido | T11: Por registrar | U11: Por registrar
A12: 8 | B12: Caracterización molecular, fenotípica y clonogénica de un inhibidor dual EGFR/PI3K identificado mediante virtual screening y de la terapia combinada sinérgica como estrategia de vulnerabilidad sintética in vitro en cáncer de mama triple negativo | C12: Richard Zapata Dongo | D12: — | E12: CIPHER-LAC; SAByQ | F12: Inmunidad, cáncer y enfermedades crónicas | G12: =IFERROR(INDEX('Líneas UCSUR'!$B$5:$B$41,MATCH(F12,'Líneas UCSUR'!$C$5:$C$41,0)),"") -> Salud y bienestar | H12: En concurso «Semilla Cabieses» | I12: Concursable – en evaluación | J12: 20000 | K12: Por registrar | L12: UCSUR | M12: N.º 034-2026-PRO99 | N12: =IF(M12="Por registrar","No","Sí") -> Sí | O12: 46054 | P12: 46600 | Q12: En ejecución | R12: Frontiers / PLOS ONE | S12: Sometido | T12: Por registrar | U12: Por registrar
A13: 9 | B13: Identificación biocomputacional de un sitio alostérico en la oncoproteína ALK con potencial inhibitorio empleando el reposicionamiento farmacológico como estrategia para eludir la resistencia en cáncer de pulmón de células no pequeñas (CPCNP) | C13: Pedro Ruiz Campos; Richard Zapata Dongo | D13: — | E13: CIPHER-LAC; SAByQ | F13: Inmunidad, cáncer y enfermedades crónicas | G13: =IFERROR(INDEX('Líneas UCSUR'!$B$5:$B$41,MATCH(F13,'Líneas UCSUR'!$C$5:$C$41,0)),"") -> Salud y bienestar | H13: En concurso «Semilla Cabieses» | I13: Concursable – en evaluación | J13: 20000 | K13: Por registrar | L13: UCSUR | M13: N.º 033-2026-PRO99 | N13: =IF(M13="Por registrar","No","Sí") -> Sí | O13: 46054 | P13: 46600 | Q13: En ejecución | R13: Frontiers / PLOS ONE | S13: Sometido | T13: Por registrar | U13: Por registrar
A14: 10 | B14: Precision Nutraceuticals and Biomarkers of Healthy Aging: A Scoping Review of Human Studies on Nutrigenomic-Based Interventions | C14: Moisés Apolaya Segura | D14: — | E14: CIPHER-LAC | F14: Nutrición, bienestar y actividad física | G14: =IFERROR(INDEX('Líneas UCSUR'!$B$5:$B$41,MATCH(F14,'Líneas UCSUR'!$C$5:$C$41,0)),"") -> Salud y bienestar | H14: Ninguna | I14: Sin financiamiento | J14: Por registrar | K14: Por registrar | L14: UCSUR | M14: PI-50-2026-1941 | N14: =IF(M14="Por registrar","No","Sí") -> Sí | O14: 46054 | P14: 46235 | Q14: Finalizado – publicado | R14: Medical Sciences | S14: Publicado | T14: Por registrar | U14: Por registrar
B16: * Costo monetario: se transcribe el valor del registro original (40 y 20); la unidad (soles, miles de soles o USD) no está especificada y debe confirmarse con los investigadores líderes.
B17: Estado de ejecución: inferido por la coordinación a partir de las fechas y del estado de difusión registrados (ej. artículo publicado = finalizado). Hoy: fecha de corte en hoja Resumen.

Sheet Producción científica
A1: Producción científica 2026: artículos publicados y manuscritos en proceso
A4: N.º | B4: Artículo / manuscrito | C4: Revista | D4: Fecha de publicación | E4: Datos bibliográficos | F4: Autor(es) con filiación CIPHER-LAC | G4: Estado | H4: DOI / enlace | I4: Línea de investigación UCSUR | J4: Vínculo con proyecto o tesis del grupo | K4: Hoja de origen
A5: 1 | B5: Characteristics of Authorized Clinical Trials in Peru, 2017–2025: A National Registry-Based Study | C5: Therapeutic Innovation & Regulatory Science | D5: 46265 | E5: Publicado 31 ago 2026 | F5: Fritzi Pilar Villalba-Ugarte; Luis Ttito-Paricahua (filiación 3) | G5: Publicado | H5: https://link.springer.com/article/10.1007/s43441-026-01040-9 | I5: Salud pública, salud ocupacional y gestión en salud | J5: Autores son tesistas de la Maestría en Salud Pública (Tesis N.º 5 y 6). No registrado como proyecto. | K5: ARTICULOS PUBLICADOS
A6: 2 | B6: Precision Nutraceuticals and Biomarkers of Healthy Aging: A Scoping Review of Human Studies on Nutrigenomic-Based Interventions | C6: Medical Sciences | D6: 46257 | E6: 2026;14(5):508 | F6: Moisés Apolaya-Segura (filiación 3) | G6: Publicado | H6: https://www.mdpi.com/2076-3271/14/5/508 | I6: Nutrición, bienestar y actividad física | J6: Producto del Proyecto N.º 10 (PI-50-2026-1941) | K6: ARTICULOS PUBLICADOS / PROPUESTAS
A7: 3 | B7: Effects of Cognitive Behavioral Therapy in Autistic Adults: A Systematic Review and Meta-Analysis of Randomized Controlled Trials | C7: Autism in Adulthood | D7: 46171 | E7: Publicación anticipada en línea | F7: Glauco Valdivieso-Jiménez | G7: Publicado | H7: https://doi.org/10.1177/25739581261450541 | I7: Neurociencias y salud mental | J7: Producto del Proyecto N.º 6 | K7: ARTICULOS PUBLICADOS / PROPUESTAS
A8: 4 | B8: A framework for the development and validation of an aptamer-based assay for pathogen detection using SARS-CoV-2 as a model | C8: Scientific Reports | D8: 46170 | E8: 2026;16(1):24419 | F8: Steev Loyola (filiación 3) | G8: Publicado | H8: https://www.nature.com/articles/s41598-026-55568-9 | I8: Microbiología, infecciosas y one health | J8: No registrado como proyecto del grupo. | K8: ARTICULOS PUBLICADOS
A9: 5 | B9: Neurobiological effects of psychodynamic therapies in Borderline Personality Disorder: A systematic review | C9: Psychodynamic Psychiatry | D9: — | E9: — | F9: Glauco Valdivieso Jiménez | G9: Aceptado | H9: — | I9: Neurociencias y salud mental | J9: Producto del Proyecto N.º 5 | K9: PROPUESTAS
A10: 6 | B10: Efectividad de intervenciones virtuales para el Trastorno Límite de Personalidad antes y durante pandemia de COVID-19: una revisión sistemática | C10: Journal of Technology in Behavioral Science | D10: — | E10: — | F10: Glauco Valdivieso Jiménez | G10: Sometido | H10: — | I10: Neurociencias y salud mental | J10: Producto del Proyecto N.º 7 | K10: PROPUESTAS
A11: 7 | B11: Inhibidor dual EGFR/PI3K y terapia combinada sinérgica en cáncer de mama triple negativo (manuscrito) | C11: Frontiers / PLOS ONE | D11: — | E11: — | F11: Richard Zapata Dongo | G11: Sometido | H11: — | I11: Inmunidad, cáncer y enfermedades crónicas | J11: Producto del Proyecto N.º 8 (034-2026-PRO99) | K11: PROPUESTAS
A12: 8 | B12: Sitio alostérico en la oncoproteína ALK y reposicionamiento farmacológico en CPCNP (manuscrito) | C12: Frontiers / PLOS ONE | D12: — | E12: — | F12: Pedro Ruiz Campos; Richard Zapata Dongo | G12: Sometido | H12: — | I12: Inmunidad, cáncer y enfermedades crónicas | J12: Producto del Proyecto N.º 9 (033-2026-PRO99) | K12: PROPUESTAS
B15: Resumen de la producción
B16: Estado | C16: N.º | D16: % del total
B17: Publicado | C17: =COUNTIF($G$5:$G$12,B17) -> 4 | D17: =IF($C$20=0,0,C17/$C$20) -> 0.5
B18: Aceptado | C18: =COUNTIF($G$5:$G$12,B18) -> 1 | D18: =IF($C$20=0,0,C18/$C$20) -> 0.125
B19: Sometido | C19: =COUNTIF($G$5:$G$12,B19) -> 3 | D19: =IF($C$20=0,0,C19/$C$20) -> 0.375
B20: Total | C20: =SUM(C17:C19) -> 8 | D20: =SUM(D17:D19) -> 1

Sheet Tesis 2026
A1: Tesis en curso y asesoradas por integrantes del grupo (2026)
A4: N.º | B4: Título de la tesis | C4: Tesista | D4: Asesor(a) | E4: Programa o carrera | F4: Nivel | G4: Fecha de registro | H4: Estado del registro | I4: Años desde el registro | J4: Fecha de inicio | K4: Fecha de fin | L4: Línea de investigación UCSUR | M4: Área estratégica UCSUR | N4: Artículo derivado / observaciones
A5: 1 | B5: Asociación entre el índice triglicéridos/HDL y la neuropatía periférica dolorosa en pacientes con diabetes mellitus tipo 2: estudio de casos y controles | C5: Rossana Angélica Charapaqui Jacinto | D5: Moisés Apolaya Segura | E5: Maestría en Epidemiología Clínica y Bioestadística | F5: Posgrado | G5: 46102 | H5: =IF(ISNUMBER(G5),"Registrada","Pendiente de registro") -> Registrada | I5: =IF(ISNUMBER(G5),ROUND((Resumen!$C$5-G5)/365.25,1),"—") -> 0.5 | J5: Por registrar | K5: Por registrar | L5: Inmunidad, cáncer y enfermedades crónicas | M5: =IFERROR(INDEX('Líneas UCSUR'!$B$5:$B$41,MATCH(L5,'Líneas UCSUR'!$C$5:$C$41,0)),"") -> Salud y bienestar | N5: —
A6: 2 | B6: Colonización intestinal intrahospitalaria de Escherichia coli productora de betalactamasas de espectro extendido en perros hospitalizados en clínicas veterinarias de Lima, Perú | C6: Valeria Nicole Morales García | D6: Jhonathan Bazalar Gonzales | E6: Medicina Veterinaria y Zootecnia | F6: Pregrado | G6: 46132 | H6: =IF(ISNUMBER(G6),"Registrada","Pendiente de registro") -> Registrada | I6: =IF(ISNUMBER(G6),ROUND((Resumen!$C$5-G6)/365.25,1),"—") -> 0.4 | J6: Por registrar | K6: Por registrar | L6: Microbiología, infecciosas y one health | M6: =IFERROR(INDEX('Líneas UCSUR'!$B$5:$B$41,MATCH(L6,'Líneas UCSUR'!$C$5:$C$41,0)),"") -> Salud y bienestar | N6: Vinculada al Proyecto N.º 2 (SANIGEN)
A7: 3 | B7: Adquisición nosocomial de Klebsiella spp. productora de carbapenemasas en pacientes caninos internados en servicios de hospitalización veterinaria en Lima, Perú | C7: Brenda Lizeth Eguizabal Vílchez | D7: Jhonathan Bazalar Gonzales | E7: Medicina Veterinaria y Zootecnia | F7: Pregrado | G7: Todavía no ha sido registrado | H7: =IF(ISNUMBER(G7),"Registrada","Pendiente de registro") -> Pendiente de registro | I7: =IF(ISNUMBER(G7),ROUND((Resumen!$C$5-G7)/365.25,1),"—") -> — | J7: Por registrar | K7: Por registrar | L7: Microbiología, infecciosas y one health | M7: =IFERROR(INDEX('Líneas UCSUR'!$B$5:$B$41,MATCH(L7,'Líneas UCSUR'!$C$5:$C$41,0)),"") -> Salud y bienestar | N7: Vinculada al Proyecto N.º 2 (SANIGEN). Registro pendiente.
A8: 4 | B8: Factores asociados al abandono de tratamiento en pacientes con Trastorno Límite de Personalidad en un hospital general durante 2016-2023 | C8: Glauco Valdivieso Jiménez | D8: Yamilée Hurtado Roca | E8: Maestría en Epidemiología Clínica y Bioestadística | F8: Posgrado | G8: 45391 | H8: =IF(ISNUMBER(G8),"Registrada","Pendiente de registro") -> Registrada | I8: =IF(ISNUMBER(G8),ROUND((Resumen!$C$5-G8)/365.25,1),"—") -> 2.5 | J8: Por registrar | K8: Por registrar | L8: Neurociencias y salud mental | M8: =IFERROR(INDEX('Líneas UCSUR'!$B$5:$B$41,MATCH(L8,'Líneas UCSUR'!$C$5:$C$41,0)),"") -> Salud y bienestar | N8: Tesista con 1 artículo publicado, 1 aceptado y 1 sometido en la misma línea (TLP / salud mental).
A9: 5 | B9: Desigualdades y factores asociados al acceso al continuo de atención materna en mujeres peruanas de 15 a 49 años según la Encuesta Demográfica y de Salud Familiar 2024 | C9: Fritzi Pilar Villalba Ugarte | D9: Akram Abdul Hernández Vásquez | E9: Maestría en Salud Pública | F9: Posgrado | G9: 45940 | H9: =IF(ISNUMBER(G9),"Registrada","Pendiente de registro") -> Registrada | I9: =IF(ISNUMBER(G9),ROUND((Resumen!$C$5-G9)/365.25,1),"—") -> 1 | J9: Por registrar | K9: Por registrar | L9: Salud pública, salud ocupacional y gestión en salud | M9: =IFERROR(INDEX('Líneas UCSUR'!$B$5:$B$41,MATCH(L9,'Líneas UCSUR'!$C$5:$C$41,0)),"") -> Salud y bienestar | N9: Tesista coautora de artículo en Therapeutic Innovation & Regulatory Science (2026).
A10: 6 | B10: Índice de cobertura compuesta en salud maternoinfantil en el Perú: análisis departamental 2019 y 2024 según la Encuesta Demográfica y de Salud Familiar | C10: Luis Fernando Ttito Paricahua | D10: Akram Abdul Hernández Vásquez | E10: Maestría en Salud Pública | F10: Posgrado | G10: 45940 | H10: =IF(ISNUMBER(G10),"Registrada","Pendiente de registro") -> Registrada | I10: =IF(ISNUMBER(G10),ROUND((Resumen!$C$5-G10)/365.25,1),"—") -> 1 | J10: Por registrar | K10: Por registrar | L10: Salud pública, salud ocupacional y gestión en salud | M10: =IFERROR(INDEX('Líneas UCSUR'!$B$5:$B$41,MATCH(L10,'Líneas UCSUR'!$C$5:$C$41,0)),"") -> Salud y bienestar | N10: Tesista coautor de artículo en Therapeutic Innovation & Regulatory Science (2026).
A11: 7 | B11: Factores asociados a la oportunidad en la atención prehospitalaria de casos sospechosos de enfermedad cerebrovascular aguda | C11: David Fernando Zavala Curzo | D11: Yamilée Hurtado Roca | E11: Maestría en Epidemiología Clínica y Bioestadística | F11: Posgrado | G11: 45272 | H11: =IF(ISNUMBER(G11),"Registrada","Pendiente de registro") -> Registrada | I11: =IF(ISNUMBER(G11),ROUND((Resumen!$C$5-G11)/365.25,1),"—") -> 2.8 | J11: Por registrar | K11: Por registrar | L11: Salud pública, salud ocupacional y gestión en salud | M11: =IFERROR(INDEX('Líneas UCSUR'!$B$5:$B$41,MATCH(L11,'Líneas UCSUR'!$C$5:$C$41,0)),"") -> Salud y bienestar | N11: —
A12: 8 | B12: Análisis de planes y estrategias de salud bucal en Perú, 2000-2024 | C12: Susy Rocío Ávila Herrera | D12: Yamilée Hurtado Roca | E12: Maestría en Salud Pública | F12: Posgrado | G12: Todavía no ha sido registrado | H12: =IF(ISNUMBER(G12),"Registrada","Pendiente de registro") -> Pendiente de registro | I12: =IF(ISNUMBER(G12),ROUND((Resumen!$C$5-G12)/365.25,1),"—") -> — | J12: Por registrar | K12: Por registrar | L12: Estomatología y salud bucodental | M12: =IFERROR(INDEX('Líneas UCSUR'!$B$5:$B$41,MATCH(L12,'Líneas UCSUR'!$C$5:$C$41,0)),"") -> Salud y bienestar | N12: Registro pendiente.
A13: 9 | B13: Terapia antibiótica definitiva y mortalidad a 30 días en bacteriemias por Enterobacterales productores de AmpC: comparación entre no carbapenémicos y carbapenémicos. Cohorte retrospectiva en un hospital público de referencia en Lima-Perú, 2020–2025 | C13: Anderson Reyna Alva | D13: Giancarlo Pérez Lazo | E13: Medicina Humana | F13: Pregrado | G13: 45972 | H13: =IF(ISNUMBER(G13),"Registrada","Pendiente de registro") -> Registrada | I13: =IF(ISNUMBER(G13),ROUND((Resumen!$C$5-G13)/365.25,1),"—") -> 0.9 | J13: Por registrar | K13: Por registrar | L13: Microbiología, infecciosas y one health | M13: =IFERROR(INDEX('Líneas UCSUR'!$B$5:$B$41,MATCH(L13,'Líneas UCSUR'!$C$5:$C$41,0)),"") -> Salud y bienestar | N13: —
A14: 10 | B14: Resultados de la aplicación de un curso-taller de lectura crítica sobre las habilidades en lectura crítica de revisiones sistemáticas en médicos especialistas en administración y gestión en salud que laboran en el sector salud en el Perú | C14: Nieves Zeta Ruiz | D14: Joshi Acosta Barriga | E14: Maestría en Epidemiología Clínica y Bioestadística | F14: Posgrado | G14: 44921 | H14: =IF(ISNUMBER(G14),"Registrada","Pendiente de registro") -> Registrada | I14: =IF(ISNUMBER(G14),ROUND((Resumen!$C$5-G14)/365.25,1),"—") -> 3.7 | J14: Por registrar | K14: Por registrar | L14: Innovación educativa y simulación en salud | M14: =IFERROR(INDEX('Líneas UCSUR'!$B$5:$B$41,MATCH(L14,'Líneas UCSUR'!$C$5:$C$41,0)),"") -> Sociedad y ciudadanía | N14: —
A15: 11 | B15: Completitud del reporte, calidad metodológica y riesgo de sesgo en estudios de modelos de inteligencia artificial para la predicción diagnóstica clínica con datos de población peruana: protocolo de revisión sistemática metodológica | C15: Judith Quiñones Inga | D15: Maguiña (nombre completo por registrar) | E15: Maestría en Epidemiología Clínica y Bioestadística | F15: Posgrado | G15: 46264 | H15: =IF(ISNUMBER(G15),"Registrada","Pendiente de registro") -> Registrada | I15: =IF(ISNUMBER(G15),ROUND((Resumen!$C$5-G15)/365.25,1),"—") -> 0.1 | J15: Por registrar | K15: Por registrar | L15: Salud basada en evidencias | M15: =IFERROR(INDEX('Líneas UCSUR'!$B$5:$B$41,MATCH(L15,'Líneas UCSUR'!$C$5:$C$41,0)),"") -> Salud y bienestar | N15: —
B16: Celdas en ámbar: tesis con 2 años o más desde su registro (priorizar culminación y sustentación). Fechas de inicio y fin vacías en el registro original.
B18: Resumen de tesis
B19: Programa o carrera | C19: N.º de tesis | D19: Registradas
B20: Maestría en Epidemiología Clínica y Bioestadística | C20: =COUNTIF($E$5:$E$15,B20) -> 5 | D20: =COUNTIFS($E$5:$E$15,B20,$H$5:$H$15,"Registrada") -> 5
B21: Maestría en Salud Pública | C21: =COUNTIF($E$5:$E$15,B21) -> 3 | D21: =COUNTIFS($E$5:$E$15,B21,$H$5:$H$15,"Registrada") -> 2
B22: Medicina Veterinaria y Zootecnia | C22: =COUNTIF($E$5:$E$15,B22) -> 2 | D22: =COUNTIFS($E$5:$E$15,B22,$H$5:$H$15,"Registrada") -> 1
B23: Medicina Humana | C23: =COUNTIF($E$5:$E$15,B23) -> 1 | D23: =COUNTIFS($E$5:$E$15,B23,$H$5:$H$15,"Registrada") -> 1
B24: Total | C24: =SUM(C20:C23) -> 11 | D24: =SUM(D20:D23) -> 9
B26: Asesor(a) | C26: Tesis asesoradas
B27: Yamilée Hurtado Roca | C27: =COUNTIF($D$5:$D$15,B27) -> 3
B28: Akram Abdul Hernández Vásquez | C28: =COUNTIF($D$5:$D$15,B28) -> 2
B29: Jhonathan Bazalar Gonzales | C29: =COUNTIF($D$5:$D$15,B29) -> 2
B30: Moisés Apolaya Segura | C30: =COUNTIF($D$5:$D$15,B30) -> 1
B31: Joshi Acosta Barriga | C31: =COUNTIF($D$5:$D$15,B31) -> 1
B32: Giancarlo Pérez Lazo | C32: =COUNTIF($D$5:$D$15,B32) -> 1
B33: Maguiña (nombre completo por registrar) | C33: =COUNTIF($D$5:$D$15,B33) -> 1

Sheet Postulaciones
A1: Postulaciones a fondos concursables
A4: N.º | B4: Convocatoria | C4: Propuesta | D4: Investigador(a) líder | E4: Investigadores colaboradores | F4: Equipo investigador | G4: Fecha de envío | H4: Fecha de respuesta (según bases) | I4: Línea de investigación UCSUR | J4: Adjudicación de fondo | K4: Estado a la fecha de corte
A5: 1 | B5: Proyectos de Investigación Básica 2026-01 | C5: Caracterización genómica del resistoma y viruloma de bacterias patógenas en los Andes Centrales mediante secuenciación de tercera generación | D5: Joshi Acosta Barriga | E5: María Pons; Franck Quispe; María Eguiluz | F5: Por registrar | G5: 46077 | H5: A partir del 24 de junio de 2026 | I5: Microbiología, infecciosas y one health | J5: A partir de agosto de 2026 | K5: En evaluación – resultado por confirmar
B8: Otros fondos en concurso registrados en la hoja de proyectos
B9: Proyecto | C9: Investigador(a) líder | D9: Fondo | E9: Estado | F9: Referencia
B10: ='Proyectos 2026'!B12 -> Caracterización molecular, fenotípica y clonogénica de un inhibidor dual EGFR/PI3K identificado mediante virtual screening y de la terapia combinada sinérgica como estrategia de vulnerabilidad sintética in vitro en cáncer de mama triple negativo | C10: ='Proyectos 2026'!C12 -> Richard Zapata Dongo | D10: ='Proyectos 2026'!H12 -> En concurso «Semilla Cabieses» | E10: En evaluación – resultado por confirmar | F10: Proyecto N.º 8
B11: ='Proyectos 2026'!B13 -> Identificación biocomputacional de un sitio alostérico en la oncoproteína ALK con potencial inhibitorio empleando el reposicionamiento farmacológico como estrategia para eludir la resistencia en cáncer de pulmón de células no pequeñas (CPCNP) | C11: ='Proyectos 2026'!C13 -> Pedro Ruiz Campos; Richard Zapata Dongo | D11: ='Proyectos 2026'!H13 -> En concurso «Semilla Cabieses» | E11: En evaluación – resultado por confirmar | F11: Proyecto N.º 9

Sheet Difusión CTI
A1: Webinars y actividades de difusión CTI
A4: N.º | B4: Título propuesto | C4: Responsable (coordina con panelistas y comunicaciones) | D4: Moderador(a) | E4: Panelistas | F4: Fecha del evento | G4: Envío de insumos a Comunicaciones | H4: Inicio de difusión
B14: Estado de la difusión en los proyectos
B15: Indicador | C15: N.º | D15: Fuente
B16: Webinars registrados | C16: =COUNTA(B5:B10) -> 0 | D16: Esta hoja
B17: Proyectos con webinar registrado | C17: =COUNTIFS('Proyectos 2026'!T5:T14,"<>Por registrar",'Proyectos 2026'!T5:T14,"<>") -> 0 | D17: Proyectos 2026, col. T
B18: Proyectos con acción de incidencia en políticas registrada | C18: =COUNTIFS('Proyectos 2026'!U5:U14,"<>Por registrar",'Proyectos 2026'!U5:U14,"<>") -> 0 | D18: Proyectos 2026, col. U
B19: Proyectos con artículo enviado, aceptado o publicado | C19: =COUNTIF('Proyectos 2026'!S5:S14,"Publicado")+COUNTIF('Proyectos 2026'!S5:S14,"Aceptado")+COUNTIF('Proyectos 2026'!S5:S14,"Sometido") -> 6 | D19: Proyectos 2026, col. S
B21: Oportunidades de difusión identificadas (propuesta de la coordinación)
B22: Tema propuesto | C22: Insumo del grupo | D22: Responsable sugerido | E22: Formato
B23: Ensayos clínicos autorizados en el Perú 2017–2025: qué nos dice el registro nacional | C23: Artículo publicado en Therapeutic Innovation & Regulatory Science | D23: Fritzi Villalba Ugarte; Luis Ttito Paricahua | E23: Webinar
B24: Salud mental basada en evidencias: psicoterapias en TLP y autismo en la adultez | C24: 1 artículo publicado, 1 aceptado y 1 sometido (Proyectos 5–7) | D24: Glauco Valdivieso Jiménez | E24: Webinar
B25: Una Salud: resistencia antimicrobiana e influenza zoonótica | C25: Proyectos 2 y 3, tesis de MVZ y Medicina, postulación de investigación básica | D25: Natalia Vargas Herrera; Jhonathan Bazalar Gonzales | E25: Webinar / nota de política
B26: Nutracéuticos de precisión y envejecimiento saludable | C26: Artículo publicado en Medical Sciences | D26: Moisés Apolaya Segura | E26: Webinar

Sheet Equipo
A1: Integrantes y participación en las actividades del grupo
A4: N.º | B4: Nombre | C4: Clave de búsqueda | D4: Tipo de participación | E4: Proyectos (líder) | F4: Proyectos (colaborador) | G4: Artículos y manuscritos | H4: Tesis (asesor/a) | I4: Tesis (tesista) | J4: Postulaciones | K4: Total de participaciones | L4: Rol principal en 2026
A5: 1 | B5: Glauco Valdivieso Jiménez | C5: Valdivieso | D5: Investigador / tesista de posgrado | E5: =COUNTIF('Proyectos 2026'!$C$5:$C$14,"*"&C5&"*") -> 2 | F5: =COUNTIF('Proyectos 2026'!$D$5:$D$14,"*"&C5&"*") -> 2 | G5: =COUNTIF('Producción científica'!$F$5:$F$12,"*"&C5&"*") -> 3 | H5: =COUNTIF('Tesis 2026'!$D$5:$D$15,"*"&C5&"*") -> 0 | I5: =COUNTIF('Tesis 2026'!$C$5:$C$15,"*"&C5&"*") -> 1 | J5: =COUNTIF(Postulaciones!$D$5:$D$5,"*"&C5&"*")+COUNTIF(Postulaciones!$E$5:$E$5,"*"&C5&"*") -> 0 | K5: =SUM(E5:J5) -> 8 | L5: =IF(E5>0,"Líder de proyecto",IF(H5>0,"Asesor(a) de tesis",IF(G5>0,"Autor(a)",IF(I5>0,"Tesista","Colaborador(a)")))) -> Líder de proyecto
A6: 2 | B6: Richard Zapata Dongo | C6: Zapata | D6: Investigador | E6: =COUNTIF('Proyectos 2026'!$C$5:$C$14,"*"&C6&"*") -> 2 | F6: =COUNTIF('Proyectos 2026'!$D$5:$D$14,"*"&C6&"*") -> 0 | G6: =COUNTIF('Producción científica'!$F$5:$F$12,"*"&C6&"*") -> 2 | H6: =COUNTIF('Tesis 2026'!$D$5:$D$15,"*"&C6&"*") -> 0 | I6: =COUNTIF('Tesis 2026'!$C$5:$C$15,"*"&C6&"*") -> 0 | J6: =COUNTIF(Postulaciones!$D$5:$D$5,"*"&C6&"*")+COUNTIF(Postulaciones!$E$5:$E$5,"*"&C6&"*") -> 0 | K6: =SUM(E6:J6) -> 4 | L6: =IF(E6>0,"Líder de proyecto",IF(H6>0,"Asesor(a) de tesis",IF(G6>0,"Autor(a)",IF(I6>0,"Tesista","Colaborador(a)")))) -> Líder de proyecto
A7: 3 | B7: Moisés Apolaya Segura | C7: Apolaya | D7: Investigador | E7: =COUNTIF('Proyectos 2026'!$C$5:$C$14,"*"&C7&"*") -> 1 | F7: =COUNTIF('Proyectos 2026'!$D$5:$D$14,"*"&C7&"*") -> 0 | G7: =COUNTIF('Producción científica'!$F$5:$F$12,"*"&C7&"*") -> 1 | H7: =COUNTIF('Tesis 2026'!$D$5:$D$15,"*"&C7&"*") -> 1 | I7: =COUNTIF('Tesis 2026'!$C$5:$C$15,"*"&C7&"*") -> 0 | J7: =COUNTIF(Postulaciones!$D$5:$D$5,"*"&C7&"*")+COUNTIF(Postulaciones!$E$5:$E$5,"*"&C7&"*") -> 0 | K7: =SUM(E7:J7) -> 3 | L7: =IF(E7>0,"Líder de proyecto",IF(H7>0,"Asesor(a) de tesis",IF(G7>0,"Autor(a)",IF(I7>0,"Tesista","Colaborador(a)")))) -> Líder de proyecto
A8: 4 | B8: Yamilée Hurtado Roca | C8: Hurtado | D8: Investigadora / asesora | E8: =COUNTIF('Proyectos 2026'!$C$5:$C$14,"*"&C8&"*") -> 0 | F8: =COUNTIF('Proyectos 2026'!$D$5:$D$14,"*"&C8&"*") -> 0 | G8: =COUNTIF('Producción científica'!$F$5:$F$12,"*"&C8&"*") -> 0 | H8: =COUNTIF('Tesis 2026'!$D$5:$D$15,"*"&C8&"*") -> 3 | I8: =COUNTIF('Tesis 2026'!$C$5:$C$15,"*"&C8&"*") -> 0 | J8: =COUNTIF(Postulaciones!$D$5:$D$5,"*"&C8&"*")+COUNTIF(Postulaciones!$E$5:$E$5,"*"&C8&"*") -> 0 | K8: =SUM(E8:J8) -> 3 | L8: =IF(E8>0,"Líder de proyecto",IF(H8>0,"Asesor(a) de tesis",IF(G8>0,"Autor(a)",IF(I8>0,"Tesista","Colaborador(a)")))) -> Asesor(a) de tesis
A9: 5 | B9: Jhonathan Bazalar Gonzales | C9: Bazalar | D9: Investigador / asesor | E9: =COUNTIF('Proyectos 2026'!$C$5:$C$14,"*"&C9&"*") -> 0 | F9: =COUNTIF('Proyectos 2026'!$D$5:$D$14,"*"&C9&"*") -> 1 | G9: =COUNTIF('Producción científica'!$F$5:$F$12,"*"&C9&"*") -> 0 | H9: =COUNTIF('Tesis 2026'!$D$5:$D$15,"*"&C9&"*") -> 2 | I9: =COUNTIF('Tesis 2026'!$C$5:$C$15,"*"&C9&"*") -> 0 | J9: =COUNTIF(Postulaciones!$D$5:$D$5,"*"&C9&"*")+COUNTIF(Postulaciones!$E$5:$E$5,"*"&C9&"*") -> 0 | K9: =SUM(E9:J9) -> 3 | L9: =IF(E9>0,"Líder de proyecto",IF(H9>0,"Asesor(a) de tesis",IF(G9>0,"Autor(a)",IF(I9>0,"Tesista","Colaborador(a)")))) -> Asesor(a) de tesis
A10: 6 | B10: Akram Abdul Hernández Vásquez | C10: Hernández Vásquez | D10: Asesor | E10: =COUNTIF('Proyectos 2026'!$C$5:$C$14,"*"&C10&"*") -> 0 | F10: =COUNTIF('Proyectos 2026'!$D$5:$D$14,"*"&C10&"*") -> 0 | G10: =COUNTIF('Producción científica'!$F$5:$F$12,"*"&C10&"*") -> 0 | H10: =COUNTIF('Tesis 2026'!$D$5:$D$15,"*"&C10&"*") -> 2 | I10: =COUNTIF('Tesis 2026'!$C$5:$C$15,"*"&C10&"*") -> 0 | J10: =COUNTIF(Postulaciones!$D$5:$D$5,"*"&C10&"*")+COUNTIF(Postulaciones!$E$5:$E$5,"*"&C10&"*") -> 0 | K10: =SUM(E10:J10) -> 2 | L10: =IF(E10>0,"Líder de proyecto",IF(H10>0,"Asesor(a) de tesis",IF(G10>0,"Autor(a)",IF(I10>0,"Tesista","Colaborador(a)")))) -> Asesor(a) de tesis
A11: 7 | B11: Joshi Acosta Barriga | C11: Acosta | D11: Investigador / asesor | E11: =COUNTIF('Proyectos 2026'!$C$5:$C$14,"*"&C11&"*") -> 0 | F11: =COUNTIF('Proyectos 2026'!$D$5:$D$14,"*"&C11&"*") -> 0 | G11: =COUNTIF('Producción científica'!$F$5:$F$12,"*"&C11&"*") -> 0 | H11: =COUNTIF('Tesis 2026'!$D$5:$D$15,"*"&C11&"*") -> 1 | I11: =COUNTIF('Tesis 2026'!$C$5:$C$15,"*"&C11&"*") -> 0 | J11: =COUNTIF(Postulaciones!$D$5:$D$5,"*"&C11&"*")+COUNTIF(Postulaciones!$E$5:$E$5,"*"&C11&"*") -> 1 | K11: =SUM(E11:J11) -> 2 | L11: =IF(E11>0,"Líder de proyecto",IF(H11>0,"Asesor(a) de tesis",IF(G11>0,"Autor(a)",IF(I11>0,"Tesista","Colaborador(a)")))) -> Asesor(a) de tesis
A12: 8 | B12: Miguel Ángel Vences | C12: Vences | D12: Investigador | E12: =COUNTIF('Proyectos 2026'!$C$5:$C$14,"*"&C12&"*") -> 1 | F12: =COUNTIF('Proyectos 2026'!$D$5:$D$14,"*"&C12&"*") -> 0 | G12: =COUNTIF('Producción científica'!$F$5:$F$12,"*"&C12&"*") -> 0 | H12: =COUNTIF('Tesis 2026'!$D$5:$D$15,"*"&C12&"*") -> 0 | I12: =COUNTIF('Tesis 2026'!$C$5:$C$15,"*"&C12&"*") -> 0 | J12: =COUNTIF(Postulaciones!$D$5:$D$5,"*"&C12&"*")+COUNTIF(Postulaciones!$E$5:$E$5,"*"&C12&"*") -> 0 | K12: =SUM(E12:J12) -> 1 | L12: =IF(E12>0,"Líder de proyecto",IF(H12>0,"Asesor(a) de tesis",IF(G12>0,"Autor(a)",IF(I12>0,"Tesista","Colaborador(a)")))) -> Líder de proyecto
A13: 9 | B13: Natalia Vargas Herrera | C13: Vargas Herrera | D13: Investigadora | E13: =COUNTIF('Proyectos 2026'!$C$5:$C$14,"*"&C13&"*") -> 1 | F13: =COUNTIF('Proyectos 2026'!$D$5:$D$14,"*"&C13&"*") -> 0 | G13: =COUNTIF('Producción científica'!$F$5:$F$12,"*"&C13&"*") -> 0 | H13: =COUNTIF('Tesis 2026'!$D$5:$D$15,"*"&C13&"*") -> 0 | I13: =COUNTIF('Tesis 2026'!$C$5:$C$15,"*"&C13&"*") -> 0 | J13: =COUNTIF(Postulaciones!$D$5:$D$5,"*"&C13&"*")+COUNTIF(Postulaciones!$E$5:$E$5,"*"&C13&"*") -> 0 | K13: =SUM(E13:J13) -> 1 | L13: =IF(E13>0,"Líder de proyecto",IF(H13>0,"Asesor(a) de tesis",IF(G13>0,"Autor(a)",IF(I13>0,"Tesista","Colaborador(a)")))) -> Líder de proyecto
A14: 10 | B14: Pedro Ruiz Campos | C14: Ruiz Campos | D14: Investigador | E14: =COUNTIF('Proyectos 2026'!$C$5:$C$14,"*"&C14&"*") -> 1 | F14: =COUNTIF('Proyectos 2026'!$D$5:$D$14,"*"&C14&"*") -> 0 | G14: =COUNTIF('Producción científica'!$F$5:$F$12,"*"&C14&"*") -> 1 | H14: =COUNTIF('Tesis 2026'!$D$5:$D$15,"*"&C14&"*") -> 0 | I14: =COUNTIF('Tesis 2026'!$C$5:$C$15,"*"&C14&"*") -> 0 | J14: =COUNTIF(Postulaciones!$D$5:$D$5,"*"&C14&"*")+COUNTIF(Postulaciones!$E$5:$E$5,"*"&C14&"*") -> 0 | K14: =SUM(E14:J14) -> 2 | L14: =IF(E14>0,"Líder de proyecto",IF(H14>0,"Asesor(a) de tesis",IF(G14>0,"Autor(a)",IF(I14>0,"Tesista","Colaborador(a)")))) -> Líder de proyecto
A15: 11 | B15: Jesús Pérez Castilla | C15: Castilla | D15: Investigador | E15: =COUNTIF('Proyectos 2026'!$C$5:$C$14,"*"&C15&"*") -> 1 | F15: =COUNTIF('Proyectos 2026'!$D$5:$D$14,"*"&C15&"*") -> 0 | G15: =COUNTIF('Producción científica'!$F$5:$F$12,"*"&C15&"*") -> 0 | H15: =COUNTIF('Tesis 2026'!$D$5:$D$15,"*"&C15&"*") -> 0 | I15: =COUNTIF('Tesis 2026'!$C$5:$C$15,"*"&C15&"*") -> 0 | J15: =COUNTIF(Postulaciones!$D$5:$D$5,"*"&C15&"*")+COUNTIF(Postulaciones!$E$5:$E$5,"*"&C15&"*") -> 0 | K15: =SUM(E15:J15) -> 1 | L15: =IF(E15>0,"Líder de proyecto",IF(H15>0,"Asesor(a) de tesis",IF(G15>0,"Autor(a)",IF(I15>0,"Tesista","Colaborador(a)")))) -> Líder de proyecto
A16: 12 | B16: Aurora Döll | C16: Döll | D16: Colaboradora internacional (España) | E16: =COUNTIF('Proyectos 2026'!$C$5:$C$14,"*"&C16&"*") -> 1 | F16: =COUNTIF('Proyectos 2026'!$D$5:$D$14,"*"&C16&"*") -> 0 | G16: =COUNTIF('Producción científica'!$F$5:$F$12,"*"&C16&"*") -> 0 | H16: =COUNTIF('Tesis 2026'!$D$5:$D$15,"*"&C16&"*") -> 0 | I16: =COUNTIF('Tesis 2026'!$C$5:$C$15,"*"&C16&"*") -> 0 | J16: =COUNTIF(Postulaciones!$D$5:$D$5,"*"&C16&"*")+COUNTIF(Postulaciones!$E$5:$E$5,"*"&C16&"*") -> 0 | K16: =SUM(E16:J16) -> 1 | L16: =IF(E16>0,"Líder de proyecto",IF(H16>0,"Asesor(a) de tesis",IF(G16>0,"Autor(a)",IF(I16>0,"Tesista","Colaborador(a)")))) -> Líder de proyecto
... A32: 28 | B32: Judith Quiñones Inga | C32: Quiñones | D32: Tesista | E32: =COUNTIF('Proyectos 2026'!$C$5:$C$14,"*"&C32&"*") -> 0 | F32: =COUNTIF('Proyectos 2026'!$D$5:$D$14,"*"&C32&"*") -> 0 | G32: =COUNTIF('Producción científica'!$F$5:$F$12,"*"&C32&"*") -> 0 | H32: =COUNTIF('Tesis 2026'!$D$5:$D$15,"*"&C32&"*") -> 0 | I32: =COUNTIF('Tesis 2026'!$C$5:$C$15,"*"&C32&"*") -> 1 | J32: =COUNTIF(Postulaciones!$D$5:$D$5,"*"&C32&"*")+COUNTIF(Postulaciones!$E$5:$E$5,"*"&C32&"*") -> 0 | K32: =SUM(E32:J32) -> 1 | L32: =IF(E32>0,"Líder de proyecto",IF(H32>0,"Asesor(a) de tesis",IF(G32>0,"Autor(a)",IF(I32>0,"Tesista","Colaborador(a)")))) -> Tesista
B34: Total de integrantes registrados | C34: =COUNTA(B5:B32) -> 28
B35: Tesistas | C35: =COUNTIF(D5:D32,"*tesista*") -> 11
B36: Colaboradores internacionales | C36: =COUNTIF(D5:D32,"*internacional*") -> 1

Sheet Pendientes y acciones
A1: Vacíos de información y acciones de seguimiento
A2: Revisión de calidad del registro realizada por la coordinación del grupo. Sirve como plan de trabajo para la próxima actualización a la Dirección de Investigación.
A4: N.º | B4: Hoja | C4: Registro | D4: Hallazgo | E4: Acción de seguimiento | F4: Responsable | G4: Prioridad | H4: Estado
A5: 1 | B5: Proyectos 2026 | C5: Proyecto N.º 2 (Enterobacterales en perros) | D5: Sin investigador(a) líder UCSUR, sin fechas ni protocolo registrados; tiene 2 tesis de pregrado vinculadas. | E5: Designar líder, registrar protocolo y cronograma. | F5: Jhonathan Bazalar Gonzales | G5: Alta | H5: Pendiente
A6: 2 | B6: Proyectos 2026 | C6: Proyecto N.º 3 (influenza zoonótica, TDR-OMS) | D6: Único proyecto con entidad financiadora externa, pero sin fechas de ejecución ni protocolo registrado; unidad del costo (40) no especificada. | E6: Registrar protocolo, fechas y monto con moneda; confirmar estado del financiamiento. | F6: Natalia Vargas Herrera | G6: Alta | H6: Pendiente
A7: 3 | B7: Proyectos 2026 | C7: Proyectos N.º 8 y 9 (Semilla Cabieses) | D7: Figuran «en concurso»; costo 20 sin unidad. | E7: Actualizar resultado del concurso y precisar moneda del costo. | F7: Richard Zapata Dongo | G7: Media | H7: Pendiente
A8: 4 | B8: Proyectos 2026 | C8: Proyectos N.º 1, 3, 4, 5, 6, 7 | D8: Sin número de registro de protocolo. | E8: Registrar protocolo o indicar si no aplica (revisiones sistemáticas). | F8: Investigadores líderes | G8: Media | H8: Pendiente
A9: 5 | B9: Proyectos 2026 | C9: Proyecto N.º 7 | D9: Sin institución donde se realiza. | E9: Completar institución (UCSUR u otra). | F9: Glauco Valdivieso Jiménez | G9: Baja | H9: Pendiente
A10: 6 | B10: Proyectos 2026 | C10: Todos los proyectos | D10: Costo no monetario, webinar e incidencia en políticas vacíos en los 10 proyectos. | E10: Completar campos de difusión e incidencia. | F10: Investigadores líderes | G10: Media | H10: Pendiente
A11: 7 | B11: Producción científica | C11: Artículos en Therapeutic Innovation & Regulatory Science y Scientific Reports | D11: Publicados con filiación CIPHER-LAC, pero no están registrados como proyectos del grupo. | E11: Registrar como proyectos/productos del grupo para su trazabilidad. | F11: F. Villalba, L. Ttito, S. Loyola | G11: Media | H11: Pendiente
A12: 8 | B12: Tesis 2026 | C12: Tesis N.º 3 y 8 | D12: Todavía no registradas. | E12: Completar registro de proyecto de tesis. | F12: J. Bazalar; Y. Hurtado Roca | G12: Alta | H12: Pendiente
A13: 9 | B13: Tesis 2026 | C13: Tesis N.º 4, 7 y 10 | D13: Registradas entre 2022 y 2024 (≥ 2 años a la fecha de corte). | E13: Priorizar culminación, sustentación y envío del artículo. | F13: Y. Hurtado Roca; J. Acosta Barriga | G13: Alta | H13: Pendiente
A14: 10 | B14: Tesis 2026 | C14: Todas las tesis | D14: Fechas de inicio, fin y publicación del artículo vacías. | E14: Completar cronograma y meta de publicación. | F14: Asesores | G14: Media | H14: Pendiente
A15: 11 | B15: Tesis 2026 | C15: Tesis N.º 11 | D15: Asesor registrado solo como «Maguiña». | E15: Completar nombre del asesor. | F15: Judith Quiñones Inga | G15: Baja | H15: Pendiente
A16: 12 | B16: Postulaciones | C16: Investigación Básica 2026-01 | D16: Resultados previstos desde el 24/06/2026; adjudicación desde agosto 2026. Estado no actualizado. | E16: Actualizar resultado (adjudicado / no adjudicado) y equipo investigador. | F16: Joshi Acosta Barriga | G16: Alta | H16: Pendiente
A17: 13 | B17: Difusión CTI | C17: Webinars | D17: Ningún webinar registrado en 2026. | E17: Programar al menos un webinar por trimestre con base en los artículos publicados (ver propuestas). | F17: Coordinación CIPHER-LAC | G17: Media | H17: Pendiente
